<?xml version="1.0" ?>
<!-- =================================================================================== -->
<!-- |    This document was autogenerated by xacro from urdf/galbot_one/galbot_one.xacro | -->
<!-- |    EDITING THIS FILE BY HAND IS NOT RECOMMENDED                                 | -->
<!-- =================================================================================== -->
<!-- 
#####################################################################################
#
# Copyright (c) 2023-2024 Galbot, Inc. All Rights Reserved.
#
# This software contains confidential and proprietary information of Galbot, Inc.
# ("Confidential Information"). You shall not disclose such Confidential Information
# and shall use it only in accordance with the terms of the license agreement you
# entered into with Galbot, Inc.
#
# UNAUTHORIZED COPYING, USE, OR DISTRIBUTION OF THIS SOFTWARE, OR ANY PORTION OR
# DERIVATIVE THEREOF, IS STRICTLY PROHIBITED. IF YOU HAVE RECEIVED THIS SOFTWARE IN
# ERROR, PLEASE NOTIFY GALBOT, INC. IMMEDIATELY AND DELETE IT FROM YOUR SYSTEM.
#
#####################################################################################
#
# Description: Xacro file for Galbot One
# Author: Herman Ye@Galbot
#
#####################################################################################
-->
<robot name="galbot_one">
  <!-- ROBOT -->
  <!-- Robot Base Link -->
  <link name="base_link"/>
  <link name="omni_chassis_base_link">
    <inertial>
      <origin rpy="0 0 0" xyz="0.0075524 8.4084E-05 0.10968"/>
      <mass value="14.823"/>
      <inertia ixx="0.27707" ixy="-0.00017423" ixz="0.00046549" iyy="0.23617" iyz="-1.6815E-05" izz="0.41088"/>
    </inertial>
    <visual>
      <origin rpy="0 0 0" xyz="0 0 0"/>
      <geometry>
        <mesh filename="meshes/chassis/omni_chassis_base_link.stl"/>
      </geometry>
      <material name="">
        <color rgba="1 1 1 1"/>
      </material>
    </visual>
    <collision>
      <origin rpy="0 0 0" xyz="0 0 0"/>
      <geometry>
        <mesh filename="meshes/chassis/omni_chassis_base_link_aabb.stl"/>
      </geometry>
    </collision>
  </link>
  <joint name="base_joint" type="fixed">
    <origin rpy="0 0 0" xyz="0.134 0 0.035"/>
    <parent link="base_link"/>
    <child link="omni_chassis_base_link"/>
    <axis xyz="0 0 0"/>
  </joint>
  <link name="omni_chassis_leg_mount_link"/>
  <joint name="omni_chassis_leg_mount_joint" type="fixed">
    <origin rpy="0 0 0" xyz="0.134 0 0.035"/>
    <parent link="omni_chassis_base_link"/>
    <child link="omni_chassis_leg_mount_link"/>
    <axis xyz="0 0 0"/>
  </joint>
  <joint name="leg_joint" type="fixed">
    <origin rpy="0 0 0" xyz="0 0 0"/>
    <parent link="omni_chassis_leg_mount_link"/>
    <child link="leg_base_link"/>
  </joint>
  <link name="leg_base_link">
    <inertial>
      <origin rpy="0 0 0" xyz="-0.0012452 -0.008512 0.046468"/>
      <mass value="1.0654"/>
      <inertia ixx="0.0022657" ixy="6.7474E-19" ixz="-1.3806E-08" iyy="0.0023929" iyz="8.5925E-06" izz="0.0021664"/>
    </inertial>
    <visual>
      <origin rpy="0 0 0" xyz="0 0 0"/>
      <geometry>
        <mesh filename="meshes/leg/leg_base_link.stl"/>
      </geometry>
      <material name="">
        <color rgba="0.89804 0.91765 0.92941 1"/>
      </material>
    </visual>
    <collision>
      <origin rpy="0 0 0" xyz="0 0 0"/>
      <geometry>
        <mesh filename="meshes/leg/leg_base_link_aabb.stl"/>
      </geometry>
    </collision>
  </link>
  <link name="leg_link1">
    <inertial>
      <origin rpy="0 0 0" xyz="-0.0041532 0.23215 -0.0038806"/>
      <mass value="4.6762"/>
      <inertia ixx="0.16338" ixy="-0.0017441" ixz="0.00011587" iyy="0.019772" iyz="-0.0005703" izz="0.16014"/>
    </inertial>
    <visual>
      <origin rpy="0 0 0" xyz="0 0 0"/>
      <geometry>
        <mesh filename="meshes/leg/leg_link1.stl"/>
      </geometry>
      <material name="">
        <color rgba="0.89804 0.91765 0.92941 1"/>
      </material>
    </visual>
    <collision>
      <origin rpy="0 0 0" xyz="0 0 0"/>
      <geometry>
        <mesh filename="meshes/leg/leg_link1_aabb.stl"/>
      </geometry>
    </collision>
  </link>
  <joint name="leg_joint1" type="revolute">
    <origin rpy="1.5707963267948966 1.1858 3.141592653589793" xyz="0 0 0.128"/>
    <parent link="leg_base_link"/>
    <child link="leg_link1"/>
    <axis xyz="0 0 1"/>
    <limit effort="411" lower="0" upper="0.8834856673595296" velocity="2"/>
  </joint>
  <link name="leg_link2">
    <inertial>
      <origin rpy="0 0 0" xyz="2.3277E-06 0.20135 -0.0074786"/>
      <mass value="2.8861"/>
      <inertia ixx="0.05707" ixy="-1.5735E-06" ixz="-1.699E-08" iyy="0.0040153" iyz="-1.6592E-05" izz="0.060971"/>
    </inertial>
    <visual>
      <origin rpy="0 0 0" xyz="0 0 0"/>
      <geometry>
        <mesh filename="meshes/leg/leg_link2.stl"/>
      </geometry>
      <material name="">
        <color rgba="0.89804 0.91765 0.92941 1"/>
      </material>
    </visual>
    <collision>
      <origin rpy="0 0 0" xyz="0 0 0"/>
      <geometry>
        <mesh filename="meshes/leg/leg_link2_aabb.stl"/>
      </geometry>
    </collision>
  </link>
  <joint name="leg_joint2" type="revolute">
    <origin rpy="0 0 2.7566" xyz="0 0.45 0"/>
    <parent link="leg_link1"/>
    <child link="leg_link2"/>
    <axis xyz="0 0 1"/>
    <limit effort="411" lower="-3.141592653589793" upper="0" velocity="2"/>
  </joint>
  <link name="leg_link3">
    <inertial>
      <origin rpy="0 0 0" xyz="4.3015E-06 0.050547 -0.0041075"/>
      <mass value="1.2932"/>
      <inertia ixx="0.0037364" ixy="6.4237E-07" ixz="9.773E-07" iyy="0.0035864" iyz="-4.7459E-05" izz="0.0036381"/>
    </inertial>
    <visual>
      <origin rpy="0 0 0" xyz="0 0 0"/>
      <geometry>
        <mesh filename="meshes/leg/leg_link3.stl"/>
      </geometry>
      <material name="">
        <color rgba="0.89804 0.91765 0.92941 1"/>
      </material>
    </visual>
    <collision>
      <origin rpy="0 0 0" xyz="0 0 0"/>
      <geometry>
        <mesh filename="meshes/leg/leg_link3_aabb.stl"/>
      </geometry>
    </collision>
  </link>
  <joint name="leg_joint3" type="revolute">
    <origin rpy="0 0 -1.5707963267948966" xyz="0 0.39 0"/>
    <parent link="leg_link2"/>
    <child link="leg_link3"/>
    <axis xyz="0 0 1"/>
    <limit effort="157" lower="-1.57079632679" upper="+1.57079632679" velocity="2"/>
  </joint>
  <link name="leg_link4">
    <inertial>
      <origin rpy="0 0 0" xyz="8.4626E-05 -4.4739E-05 0.0053562"/>
      <mass value="0.19842"/>
      <inertia ixx="0.00016414" ixy="-2.33E-07" ixz="5.9814E-09" iyy="0.00016377" iyz="-3.1622E-09" izz="0.00032482"/>
    </inertial>
    <visual>
      <origin rpy="0 0 0" xyz="0 0 0"/>
      <geometry>
        <mesh filename="meshes/leg/leg_link4.stl"/>
      </geometry>
      <material name="">
        <color rgba="0.89804 0.91765 0.92941 1"/>
      </material>
    </visual>
    <collision>
      <origin rpy="0 0 0" xyz="0 0 0"/>
      <geometry>
        <mesh filename="meshes/leg/leg_link4_aabb.stl"/>
      </geometry>
    </collision>
  </link>
  <joint name="leg_joint4" type="revolute">
    <origin rpy="1.5707963267948966 0 -3.141592653589793" xyz="0 0.163 0"/>
    <parent link="leg_link3"/>
    <child link="leg_link4"/>
    <axis xyz="0 0 1"/>
    <limit effort="66" lower="-1.5707963267948966" upper="+1.5707963267948966" velocity="2"/>
  </joint>
  <joint name="leg_torso_mount_joint" type="fixed">
    <origin rpy="0 0 0" xyz="0 0 0.01"/>
    <parent link="leg_link4"/>
    <child link="leg_torso_mount_link"/>
    <axis xyz="0 0 1"/>
  </joint>
  <link name="leg_torso_mount_link"/>
  <joint name="torso_joint" type="fixed">
    <origin rpy="0 0 0" xyz="0 0 0"/>
    <parent link="leg_torso_mount_link"/>
    <child link="torso_base_link"/>
  </joint>
  <link name="torso_base_link">
    <inertial>
      <origin rpy="0 0 0" xyz="-0.027572 -0.0025645 0.18663"/>
      <mass value="2.9691"/>
      <inertia ixx="0.016883" ixy="7.2561E-05" ixz="-4.1323E-05" iyy="0.012009" iyz="-1.2975E-05" izz="0.0074767"/>
    </inertial>
    <visual>
      <origin rpy="0 0 0" xyz="0 0 0"/>
      <geometry>
        <mesh filename="meshes/torso/torso.stl"/>
      </geometry>
      <material name="">
        <color rgba="0.89804 0.91765 0.92941 1"/>
      </material>
    </visual>
    <collision>
      <origin rpy="0 0 0" xyz="0 0 0"/>
      <geometry>
        <mesh filename="meshes/torso/torso_aabb.stl"/>
      </geometry>
    </collision>
  </link>
  <!-- Head Mount -->
  <link name="torso_head_mount_link"/>
  <joint name="torso_head_mount_joint" type="fixed">
    <origin rpy="0 0 0" xyz="0 0 0.2875"/>
    <parent link="torso_base_link"/>
    <child link="torso_head_mount_link"/>
    <axis xyz="0 0 0"/>
  </joint>
  <!-- Right Arm Mount -->
  <link name="torso_right_arm_mount_link"/>
  <joint name="torso_right_arm_mount_joint" type="fixed">
    <origin rpy="1.5707963267948966 -1.5707963267948966 0" xyz="0 -0.11805 0.2375"/>
    <parent link="torso_base_link"/>
    <child link="torso_right_arm_mount_link"/>
    <axis xyz="0 0 0"/>
  </joint>
  <!-- Left Arm Mount -->
  <link name="torso_left_arm_mount_link"> </link>
  <joint name="torso_left_arm_mount_joint" type="fixed">
    <origin rpy="1.5707963267948966 -1.5707963267948966 0" xyz="0 0.11805 0.2375"/>
    <parent link="torso_base_link"/>
    <child link="torso_left_arm_mount_link"/>
    <axis xyz="0 0 0"/>
  </joint>
  <joint name="head_joint" type="fixed">
    <origin rpy="0 0 0" xyz="0 0 0"/>
    <parent link="torso_head_mount_link"/>
    <child link="head_base_link"/>
  </joint>
  <link name="head_base_link">
    <inertial>
      <origin rpy="0 0 0" xyz="2.8174E-05 4.4192E-05 0.026611"/>
      <mass value="0.34013"/>
      <inertia ixx="0.00017046" ixy="-1.5263E-08" ixz="2.7006E-07" iyy="0.00023937" iyz="4.4134E-07" izz="0.00023946"/>
    </inertial>
    <visual>
      <origin rpy="0 0 0" xyz="0 0 0"/>
      <geometry>
        <mesh filename="meshes/head/head_base_link.stl"/>
      </geometry>
      <material name="">
        <color rgba="0.89804 0.91765 0.92941 1"/>
      </material>
    </visual>
    <collision>
      <origin rpy="0 0 0" xyz="0 0 0"/>
      <geometry>
        <mesh filename="meshes/head/head_base_link_aabb.stl"/>
      </geometry>
    </collision>
  </link>
  <link name="head_motor_yaw_link">
    <inertial>
      <origin rpy="0 0 0" xyz="0.060943 -0.0042049 0.013422"/>
      <mass value="0.3007"/>
      <inertia ixx="0.00017407" ixy="5.4933E-07" ixz="1.9726E-07" iyy="0.0002335" iyz="-4.3666E-07" izz="0.00023763"/>
    </inertial>
    <visual>
      <origin rpy="0 0 0" xyz="0 0 0"/>
      <geometry>
        <mesh filename="meshes/head/head_motor_yaw_link.stl"/>
      </geometry>
      <material name="">
        <color rgba="0.89804 0.91765 0.92941 1"/>
      </material>
    </visual>
    <collision>
      <origin rpy="0 0 0" xyz="0 0 0"/>
      <geometry>
        <mesh filename="meshes/head/head_motor_yaw_link_aabb.stl"/>
      </geometry>
    </collision>
  </link>
  <joint name="head_motor_yaw_joint" type="revolute">
    <!-- <origin rpy="0 0 0" xyz="0 0 0"/> -->
    <origin rpy="0 0 0" xyz="0 0 0.0746"/>
    <parent link="head_base_link"/>
    <child link="head_motor_yaw_link"/>
    <axis xyz="0 0 1"/>
    <!-- Constrain the yaw motor (-90, +90) -->
    <limit effort="60" lower="-1.5707963267948966" upper="1.5707963267948966" velocity="1.5"/>
    <dynamics damping="0.5" friction="0"/>
  </joint>
  <link name="head_motor_pitch_link">
    <inertial>
      <origin rpy="0 0 0" xyz="0.046748 0.0077596 -0.033083"/>
      <mass value="0.56901"/>
      <inertia ixx="0.0032613" ixy="8.7738E-06" ixz="-2.3333E-06" iyy="0.0031112" iyz="1.3221E-06" izz="0.0015503"/>
    </inertial>
    <visual>
      <origin rpy="0 0 0" xyz="0 0 0"/>
      <geometry>
        <mesh filename="meshes/head/head_motor_pitch_link.stl"/>
      </geometry>
      <material name="">
        <color rgba="0.89804 0.91765 0.92941 1"/>
      </material>
    </visual>
    <collision>
      <origin rpy="0 0 0" xyz="0 0 0"/>
      <geometry>
        <mesh filename="meshes/head/head_motor_pitch_link_aabb.stl"/>
      </geometry>
    </collision>
  </link>
  <joint name="head_motor_pitch_joint" type="revolute">
    <origin rpy="1.5707963267948966 -1.5707963267948966 0" xyz="0.074 -0.0345 0.0146"/>
    <parent link="head_motor_yaw_link"/>
    <child link="head_motor_pitch_link"/>
    <axis xyz="0 0 1"/>
    <!-- Constrain the pitch motor (-70, +3) -->
    <limit effort="60" lower="-1.2217304763960306" upper="0.05235987755982988" velocity="1.5"/>
    <dynamics damping="0.5" friction="0"/>
  </joint>
  <link name="head_camera_mount_link">
    <inertial>
      <origin rpy="0 0 0" xyz="-0.055827 0.032071 0.0047467"/>
      <mass value="0.30512"/>
      <inertia ixx="0.00025424" ixy="-1.1252E-06" ixz="2.9462E-05" iyy="0.00047177" iyz="9.9043E-08" izz="0.00067985"/>
    </inertial>
    <visual>
      <origin rpy="0 0 0" xyz="0 0 0"/>
      <geometry>
        <mesh filename="meshes/head/head_camera_link.stl"/>
      </geometry>
      <material name="">
        <color rgba="1 1 1 1"/>
      </material>
    </visual>
    <collision>
      <origin rpy="0 0 0" xyz="0 0 0"/>
      <geometry>
        <mesh filename="meshes/head/head_camera_link_aabb.stl"/>
      </geometry>
    </collision>
  </link>
  <joint name="head_camera_mount_joint" type="fixed">
    <origin rpy="-1.5707963267948966 0 -1.5707963267948966" xyz="0.091 -0.0566 -0.0035"/>
    <parent link="head_motor_pitch_link"/>
    <child link="head_camera_mount_link"/>
    <axis xyz="0 0 0"/>
  </joint>
  <joint name="left_arm_joint" type="fixed">
    <origin rpy="-3.141592653589793 0 1.5707963267948966" xyz="0 0 0"/>
    <parent link="torso_left_arm_mount_link"/>
    <child link="left_arm_base_link"/>
  </joint>
  <link name="left_arm_base_link">
    <inertial>
      <origin rpy="0 0 0" xyz="0.00053759 -0.0064563 0.047133"/>
      <mass value="0.42402"/>
      <inertia ixx="0.00032797" ixy="-3.2021E-07" ixz="7.8672E-06" iyy="0.00030712" iyz="1.1227E-06" izz="0.0003995"/>
    </inertial>
    <visual>
      <origin rpy="0 0 0" xyz="0 0 0"/>
      <geometry>
        <mesh filename="meshes/arm/base_link.stl"/>
      </geometry>
      <material name="">
        <color rgba="0.75294 0.75294 0.75294 1"/>
      </material>
    </visual>
    <collision>
      <origin rpy="0 0 0" xyz="0 0 0"/>
      <geometry>
        <mesh filename="meshes/arm/base_link_aabb.stl"/>
      </geometry>
    </collision>
  </link>
  <link name="left_arm_link1">
    <inertial>
      <origin rpy="0 0 0" xyz="-0.00053387 0.0013806 -0.0079585"/>
      <mass value="0.41938"/>
      <inertia ixx="0.00033462" ixy="-7.7588E-06" ixz="-6.7213E-07" iyy="0.00037323" iyz="2.132E-05" izz="0.00032753"/>
    </inertial>
    <visual>
      <origin rpy="0 0 0" xyz="0 0 0"/>
      <geometry>
        <mesh filename="meshes/arm/link1.stl"/>
      </geometry>
      <material name="">
        <color rgba="0.75294 0.75294 0.75294 1"/>
      </material>
    </visual>
    <collision>
      <origin rpy="0 0 0" xyz="0 0 0"/>
      <geometry>
        <mesh filename="meshes/arm/link1_aabb.stl"/>
      </geometry>
    </collision>
  </link>
  <joint name="left_arm_joint1" type="revolute">
    <origin rpy="0 0 1.5707963267948966" xyz="0 0 0.16"/>
    <parent link="left_arm_base_link"/>
    <child link="left_arm_link1"/>
    <axis xyz="0 0 1"/>
    <limit effort="60" lower="-2.94" upper="2.94" velocity="1.5"/>
  </joint>
  <link name="left_arm_link2">
    <inertial>
      <origin rpy="0 0 0" xyz="5.6769E-05 0.12878 0.0099789"/>
      <mass value="0.35274"/>
      <inertia ixx="0.00041467" ixy="6.6686E-07" ixz="2.7602E-07" iyy="0.00023745" iyz="4.3582E-05" izz="0.00041598"/>
    </inertial>
    <visual>
      <origin rpy="0 0 0" xyz="0 0 0"/>
      <geometry>
        <mesh filename="meshes/arm/link2.stl"/>
      </geometry>
      <material name="">
        <color rgba="0.75294 0.75294 0.75294 1"/>
      </material>
    </visual>
    <collision>
      <origin rpy="0 0 0" xyz="0 0 0"/>
      <geometry>
        <mesh filename="meshes/arm/link2_aabb.stl"/>
      </geometry>
    </collision>
  </link>
  <joint name="left_arm_joint2" type="revolute">
    <origin rpy="-1.5707963267948966 3.141592653589793 0" xyz="0 0 0"/>
    <parent link="left_arm_link1"/>
    <child link="left_arm_link2"/>
    <axis xyz="0 0 1"/>
    <limit effort="60" lower="-2.1" upper="1.57" velocity="1.5"/>
  </joint>
  <link name="left_arm_link3">
    <inertial>
      <origin rpy="0 0 0" xyz="-0.00033263 -0.0012705 -0.013763"/>
      <mass value="0.29633"/>
      <inertia ixx="0.00035616" ixy="3.2634E-06" ixz="1.0656E-06" iyy="0.00035666" iyz="-2.912E-06" izz="0.00016442"/>
    </inertial>
    <visual>
      <origin rpy="0 0 0" xyz="0 0 0"/>
      <geometry>
        <mesh filename="meshes/arm/link3.stl"/>
      </geometry>
      <material name="">
        <color rgba="0.75294 0.75294 0.75294 1"/>
      </material>
    </visual>
    <collision>
      <origin rpy="0 0 0" xyz="0 0 0"/>
      <geometry>
        <mesh filename="meshes/arm/link3_aabb.stl"/>
      </geometry>
    </collision>
  </link>
  <joint name="left_arm_joint3" type="revolute">
    <origin rpy="1.5707963267948966 -1.5707963267948966 3.141592653589793" xyz="0 0.3 0"/>
    <parent link="left_arm_link2"/>
    <child link="left_arm_link3"/>
    <axis xyz="0 0 1"/>
    <limit effort="30" lower="-2.94" upper="2.94" velocity="1.5"/>
  </joint>
  <link name="left_arm_link4">
    <inertial>
      <origin rpy="0 0 0" xyz="2.1198E-06 0.077687 0.0066608"/>
      <mass value="0.2008"/>
      <inertia ixx="0.0001258" ixy="-1.5851E-09" ixz="-3.5207E-09" iyy="0.00010461" iyz="1.7211E-05" izz="0.00012018"/>
    </inertial>
    <visual>
      <origin rpy="0 0 0" xyz="0 0 0"/>
      <geometry>
        <mesh filename="meshes/arm/link4.stl"/>
      </geometry>
      <material name="">
        <color rgba="0.75294 0.75294 0.75294 1"/>
      </material>
    </visual>
    <collision>
      <origin rpy="0 0 0" xyz="0 0 0"/>
      <geometry>
        <mesh filename="meshes/arm/link4_aabb.stl"/>
      </geometry>
    </collision>
  </link>
  <joint name="left_arm_joint4" type="revolute">
    <origin rpy="1.5707963267948966 0 0" xyz="0 0 0"/>
    <parent link="left_arm_link3"/>
    <child link="left_arm_link4"/>
    <axis xyz="0 0 1"/>
    <limit effort="30" lower="-2.1" upper="2.1" velocity="1.5"/>
  </joint>
  <link name="left_arm_link5">
    <inertial>
      <origin rpy="0 0 0" xyz="-5.8154E-07 -0.016828 -0.1072"/>
      <mass value="0.30236"/>
      <inertia ixx="0.00025776" ixy="-6.7445E-10" ixz="-3.5859E-09" iyy="0.00029228" iyz="3.4788E-06" izz="0.00010798"/>
    </inertial>
    <visual>
      <origin rpy="0 0 0" xyz="0 0 0"/>
      <geometry>
        <mesh filename="meshes/arm/link5.stl"/>
      </geometry>
      <material name="">
        <color rgba="0.75294 0.75294 0.75294 1"/>
      </material>
    </visual>
    <collision>
      <origin rpy="0 0 0" xyz="0 0 0"/>
      <geometry>
        <mesh filename="meshes/arm/link5_aabb.stl"/>
      </geometry>
    </collision>
  </link>
  <joint name="left_arm_joint5" type="revolute">
    <origin rpy="-1.5707963267948966 1.5707963267948966 0" xyz="0 0.3125 0"/>
    <parent link="left_arm_link4"/>
    <child link="left_arm_link5"/>
    <axis xyz="0 0 1"/>
    <limit effort="10" lower="-2.94" upper="2.94" velocity="1.5"/>
  </joint>
  <link name="left_arm_link6">
    <inertial>
      <origin rpy="0 0 0" xyz="1.6525E-06 -0.00044516 0.0010371"/>
      <mass value="0.14462"/>
      <inertia ixx="5.2919E-05" ixy="1.1618E-09" ixz="2.443E-09" iyy="5.7022E-05" iyz="-4.9349E-07" izz="5.2342E-05"/>
    </inertial>
    <visual>
      <origin rpy="0 0 0" xyz="0 0 0"/>
      <geometry>
        <mesh filename="meshes/arm/link6.stl"/>
      </geometry>
      <material name="">
        <color rgba="0.79216 0.81961 0.93333 1"/>
      </material>
    </visual>
    <collision>
      <origin rpy="0 0 0" xyz="0 0 0"/>
      <geometry>
        <mesh filename="meshes/arm/link6_aabb.stl"/>
      </geometry>
    </collision>
  </link>
  <joint name="left_arm_joint6" type="revolute">
    <origin rpy="1.5707963267948966 -1.5707963267948966 0" xyz="0 0 0"/>
    <parent link="left_arm_link5"/>
    <child link="left_arm_link6"/>
    <axis xyz="0 0 1"/>
    <limit effort="10" lower="-1.57" upper="1.57" velocity="1.5"/>
  </joint>
  <link name="left_arm_link7">
    <inertial>
      <origin rpy="0 0 0" xyz="0.043308 -2.8972E-08 0.018548"/>
      <mass value="0.042354"/>
      <inertia ixx="2.5589E-05" ixy="2.0865E-12" ixz="1.2866E-05" iyy="4.7623E-05" iyz="-1.1256E-13" izz="4.3905E-05"/>
    </inertial>
    <visual>
      <origin rpy="0 0 0" xyz="0 0 0"/>
      <geometry>
        <mesh filename="meshes/arm/link7.stl"/>
      </geometry>
      <material name="">
        <color rgba="0.79216 0.81961 0.93333 1"/>
      </material>
    </visual>
    <collision>
      <origin rpy="0 0 0" xyz="0 0 0"/>
      <geometry>
        <mesh filename="meshes/arm/link7_aabb.stl"/>
      </geometry>
    </collision>
  </link>
  <joint name="left_arm_joint7" type="revolute">
    <origin rpy="1.5707963267948966 0 0" xyz="0 0 0"/>
    <parent link="left_arm_link6"/>
    <child link="left_arm_link7"/>
    <axis xyz="0 0 1"/>
    <limit effort="10" lower="-1.57" upper="0.69" velocity="1.5"/>
  </joint>
  <link name="left_arm_end_effector_mount_link"/>
  <joint name="left_arm_end_effector_mount_joint" type="fixed">
    <origin rpy="0 0 0" xyz="0.07 0 0"/>
    <parent link="left_arm_link7"/>
    <child link="left_arm_end_effector_mount_link"/>
    <axis xyz="0 0 0"/>
  </joint>

  <!-- Left Arm Flange: -->
  <!-- Gripper Flange: -->
  <joint name="gripper_left_joint" type="fixed">
    <origin rpy="0 1.5707963267948966 0" xyz="0 0 0"/>
    <parent link="left_arm_end_effector_mount_link"/>
    <child link="gripper_left_base_link"/>
  </joint>
  <link name="gripper_left_base_link">
    <inertial>
      <origin rpy="0 0 0" xyz="1.5645E-05 -4.1843E-06 0.038"/>
      <mass value="0.072633"/>
      <inertia ixx="5.095E-05" ixy="-4.256E-14" ixz="2.0229E-08" iyy="6.0883E-05" iyz="-4.5583E-09" izz="1.933E-05"/>
    </inertial>
    <visual>
      <origin rpy="0 0 0" xyz="0 0 0"/>
      <geometry>
        <mesh filename="meshes/gripper/gripper_inspire_base_link.dae"/>
      </geometry>
      <material name="">
        <color rgba="1 1 1 1"/>
      </material>
    </visual>
    <collision>
      <origin rpy="0 0 0" xyz="0 0 0"/>
      <geometry>
        <mesh filename="meshes/gripper/gripper_inspire_base_link_convex.stl"/>
      </geometry>
    </collision>
  </link>
  <link name="gripper_left_left_link">
    <inertial>
      <origin rpy="0 0 0" xyz="-0.018807 -0.0090021 -0.0046901"/>
      <mass value="0.010721"/>
      <inertia ixx="5.1508E-07" ixy="1.2231E-10" ixz="2.8973E-07" iyy="1.5709E-06" iyz="7.2401E-11" izz="1.6904E-06"/>
    </inertial>
    <visual>
      <origin rpy="0 0 0" xyz="0 0 0"/>
      <geometry>
        <mesh filename="meshes/gripper/gripper_inspire_left_link.dae"/>
      </geometry>
      <material name="">
        <color rgba="0.79216 0.81961 0.93333 1"/>
      </material>
    </visual>
    <collision>
      <origin rpy="0 0 0" xyz="0 0 0"/>
      <geometry>
        <mesh filename="meshes/gripper/gripper_inspire_left_link_convex.stl"/>
      </geometry>
    </collision>
  </link>
  <joint name="gripper_left_left_joint" type="prismatic">
    <origin rpy="3.141592653589793 -1.5707963267948966 0" xyz="-0.034907 -0.009 0.12953"/>
    <parent link="gripper_left_base_link"/>
    <child link="gripper_left_left_link"/>
    <axis xyz="0 0 -1"/>
    <limit effort="0" lower="-0.035" upper="0" velocity="2"/>
  </joint>
  <link name="gripper_left_right_link">
    <inertial>
      <origin rpy="0 0 0" xyz="-0.018807 0.0089979 -0.0046901"/>
      <mass value="0.010721"/>
      <inertia ixx="5.1508E-07" ixy="1.2231E-10" ixz="2.8973E-07" iyy="1.5709E-06" iyz="7.2401E-11" izz="1.6904E-06"/>
    </inertial>
    <visual>
      <origin rpy="0 0 0" xyz="0 0 0"/>
      <geometry>
        <mesh filename="meshes/gripper/gripper_inspire_right_link.dae"/>
      </geometry>
      <material name="">
        <color rgba="0.79216 0.81961 0.93333 1"/>
      </material>
    </visual>
    <collision>
      <origin rpy="0 0 0" xyz="0 0 0"/>
      <geometry>
        <mesh filename="meshes/gripper/gripper_inspire_right_link_convex.stl"/>
      </geometry>
    </collision>
  </link>
  <joint name="gripper_left_right_joint" type="prismatic">
    <origin rpy="3.141592653589793 -1.5707963267948966 3.141592653589793" xyz="0.034907 -0.009 0.12953"/>
    <parent link="gripper_left_base_link"/>
    <child link="gripper_left_right_link"/>
    <axis xyz="0 0 1"/>
    <limit effort="0" lower="0" upper="0.035" velocity="2"/>
    <!-- mimic not supported in isaac sim 2023.1.0-hotfix  -->
    <!-- <mimic joint="${name}_left_joint" multiplier="-1" offset="0" /> -->
  </joint>
  <!-- Tool Center Point -->
  <link name="left_gripper_inspire_tcp_frame"/>
  <joint name="gripper_left_tcp_joint" type="fixed">
    <origin rpy="0 3.141592653589793 0" xyz="0 0 0.13751"/>
    <parent link="gripper_left_base_link"/>
    <child link="left_gripper_inspire_tcp_frame"/>
    <axis xyz="0 0 0"/>
  </joint>

  <joint name="right_arm_joint" type="fixed">
    <origin rpy="0 0 -1.5707963267948966" xyz="0 0 0"/>
    <parent link="torso_right_arm_mount_link"/>
    <child link="right_arm_base_link"/>
  </joint>
  <link name="right_arm_base_link">
    <inertial>
      <origin rpy="0 0 0" xyz="0.00053759 -0.0064563 0.047133"/>
      <mass value="0.42402"/>
      <inertia ixx="0.00032797" ixy="-3.2021E-07" ixz="7.8672E-06" iyy="0.00030712" iyz="1.1227E-06" izz="0.0003995"/>
    </inertial>
    <visual>
      <origin rpy="0 0 0" xyz="0 0 0"/>
      <geometry>
        <mesh filename="meshes/arm/base_link.stl"/>
      </geometry>
      <material name="">
        <color rgba="0.75294 0.75294 0.75294 1"/>
      </material>
    </visual>
    <collision>
      <origin rpy="0 0 0" xyz="0 0 0"/>
      <geometry>
        <mesh filename="meshes/arm/base_link_aabb.stl"/>
      </geometry>
    </collision>
  </link>
  <link name="right_arm_link1">
    <inertial>
      <origin rpy="0 0 0" xyz="-0.00053387 0.0013806 -0.0079585"/>
      <mass value="0.41938"/>
      <inertia ixx="0.00033462" ixy="-7.7588E-06" ixz="-6.7213E-07" iyy="0.00037323" iyz="2.132E-05" izz="0.00032753"/>
    </inertial>
    <visual>
      <origin rpy="0 0 0" xyz="0 0 0"/>
      <geometry>
        <mesh filename="meshes/arm/link1.stl"/>
      </geometry>
      <material name="">
        <color rgba="0.75294 0.75294 0.75294 1"/>
      </material>
    </visual>
    <collision>
      <origin rpy="0 0 0" xyz="0 0 0"/>
      <geometry>
        <mesh filename="meshes/arm/link1_aabb.stl"/>
      </geometry>
    </collision>
  </link>
  <joint name="right_arm_joint1" type="revolute">
    <origin rpy="0 0 1.5707963267948966" xyz="0 0 0.16"/>
    <parent link="right_arm_base_link"/>
    <child link="right_arm_link1"/>
    <axis xyz="0 0 1"/>
    <limit effort="60" lower="-2.94" upper="2.94" velocity="1.5"/>
  </joint>
  <link name="right_arm_link2">
    <inertial>
      <origin rpy="0 0 0" xyz="5.6769E-05 0.12878 0.0099789"/>
      <mass value="0.35274"/>
      <inertia ixx="0.00041467" ixy="6.6686E-07" ixz="2.7602E-07" iyy="0.00023745" iyz="4.3582E-05" izz="0.00041598"/>
    </inertial>
    <visual>
      <origin rpy="0 0 0" xyz="0 0 0"/>
      <geometry>
        <mesh filename="meshes/arm/link2.stl"/>
      </geometry>
      <material name="">
        <color rgba="0.75294 0.75294 0.75294 1"/>
      </material>
    </visual>
    <collision>
      <origin rpy="0 0 0" xyz="0 0 0"/>
      <geometry>
        <mesh filename="meshes/arm/link2_aabb.stl"/>
      </geometry>
    </collision>
  </link>
  <joint name="right_arm_joint2" type="revolute">
    <origin rpy="-1.5707963267948966 3.141592653589793 0" xyz="0 0 0"/>
    <parent link="right_arm_link1"/>
    <child link="right_arm_link2"/>
    <axis xyz="0 0 1"/>
    <limit effort="60" lower="-2.1" upper="1.57" velocity="1.5"/>
  </joint>
  <link name="right_arm_link3">
    <inertial>
      <origin rpy="0 0 0" xyz="-0.00033263 -0.0012705 -0.013763"/>
      <mass value="0.29633"/>
      <inertia ixx="0.00035616" ixy="3.2634E-06" ixz="1.0656E-06" iyy="0.00035666" iyz="-2.912E-06" izz="0.00016442"/>
    </inertial>
    <visual>
      <origin rpy="0 0 0" xyz="0 0 0"/>
      <geometry>
        <mesh filename="meshes/arm/link3.stl"/>
      </geometry>
      <material name="">
        <color rgba="0.75294 0.75294 0.75294 1"/>
      </material>
    </visual>
    <collision>
      <origin rpy="0 0 0" xyz="0 0 0"/>
      <geometry>
        <mesh filename="meshes/arm/link3_aabb.stl"/>
      </geometry>
    </collision>
  </link>
  <joint name="right_arm_joint3" type="revolute">
    <origin rpy="1.5707963267948966 -1.5707963267948966 3.141592653589793" xyz="0 0.3 0"/>
    <parent link="right_arm_link2"/>
    <child link="right_arm_link3"/>
    <axis xyz="0 0 1"/>
    <limit effort="30" lower="-2.94" upper="2.94" velocity="1.5"/>
  </joint>
  <link name="right_arm_link4">
    <inertial>
      <origin rpy="0 0 0" xyz="2.1198E-06 0.077687 0.0066608"/>
      <mass value="0.2008"/>
      <inertia ixx="0.0001258" ixy="-1.5851E-09" ixz="-3.5207E-09" iyy="0.00010461" iyz="1.7211E-05" izz="0.00012018"/>
    </inertial>
    <visual>
      <origin rpy="0 0 0" xyz="0 0 0"/>
      <geometry>
        <mesh filename="meshes/arm/link4.stl"/>
      </geometry>
      <material name="">
        <color rgba="0.75294 0.75294 0.75294 1"/>
      </material>
    </visual>
    <collision>
      <origin rpy="0 0 0" xyz="0 0 0"/>
      <geometry>
        <mesh filename="meshes/arm/link4_aabb.stl"/>
      </geometry>
    </collision>
  </link>
  <joint name="right_arm_joint4" type="revolute">
    <origin rpy="1.5707963267948966 0 0" xyz="0 0 0"/>
    <parent link="right_arm_link3"/>
    <child link="right_arm_link4"/>
    <axis xyz="0 0 1"/>
    <limit effort="30" lower="-2.1" upper="2.1" velocity="1.5"/>
  </joint>
  <link name="right_arm_link5">
    <inertial>
      <origin rpy="0 0 0" xyz="-5.8154E-07 -0.016828 -0.1072"/>
      <mass value="0.30236"/>
      <inertia ixx="0.00025776" ixy="-6.7445E-10" ixz="-3.5859E-09" iyy="0.00029228" iyz="3.4788E-06" izz="0.00010798"/>
    </inertial>
    <visual>
      <origin rpy="0 0 0" xyz="0 0 0"/>
      <geometry>
        <mesh filename="meshes/arm/link5.stl"/>
      </geometry>
      <material name="">
        <color rgba="0.75294 0.75294 0.75294 1"/>
      </material>
    </visual>
    <collision>
      <origin rpy="0 0 0" xyz="0 0 0"/>
      <geometry>
        <mesh filename="meshes/arm/link5_aabb.stl"/>
      </geometry>
    </collision>
  </link>
  <joint name="right_arm_joint5" type="revolute">
    <origin rpy="-1.5707963267948966 1.5707963267948966 0" xyz="0 0.3125 0"/>
    <parent link="right_arm_link4"/>
    <child link="right_arm_link5"/>
    <axis xyz="0 0 1"/>
    <limit effort="10" lower="-2.94" upper="2.94" velocity="1.5"/>
  </joint>
  <link name="right_arm_link6">
    <inertial>
      <origin rpy="0 0 0" xyz="1.6525E-06 -0.00044516 0.0010371"/>
      <mass value="0.14462"/>
      <inertia ixx="5.2919E-05" ixy="1.1618E-09" ixz="2.443E-09" iyy="5.7022E-05" iyz="-4.9349E-07" izz="5.2342E-05"/>
    </inertial>
    <visual>
      <origin rpy="0 0 0" xyz="0 0 0"/>
      <geometry>
        <mesh filename="meshes/arm/link6.stl"/>
      </geometry>
      <material name="">
        <color rgba="0.79216 0.81961 0.93333 1"/>
      </material>
    </visual>
    <collision>
      <origin rpy="0 0 0" xyz="0 0 0"/>
      <geometry>
        <mesh filename="meshes/arm/link6_aabb.stl"/>
      </geometry>
    </collision>
  </link>
  <joint name="right_arm_joint6" type="revolute">
    <origin rpy="1.5707963267948966 -1.5707963267948966 0" xyz="0 0 0"/>
    <parent link="right_arm_link5"/>
    <child link="right_arm_link6"/>
    <axis xyz="0 0 1"/>
    <limit effort="10" lower="-1.57" upper="1.57" velocity="1.5"/>
  </joint>
  <link name="right_arm_link7">
    <inertial>
      <origin rpy="0 0 0" xyz="0.043308 -2.8972E-08 0.018548"/>
      <mass value="0.042354"/>
      <inertia ixx="2.5589E-05" ixy="2.0865E-12" ixz="1.2866E-05" iyy="4.7623E-05" iyz="-1.1256E-13" izz="4.3905E-05"/>
    </inertial>
    <visual>
      <origin rpy="0 0 0" xyz="0 0 0"/>
      <geometry>
        <mesh filename="meshes/arm/link7.stl"/>
      </geometry>
      <material name="">
        <color rgba="0.79216 0.81961 0.93333 1"/>
      </material>
    </visual>
    <collision>
      <origin rpy="0 0 0" xyz="0 0 0"/>
      <geometry>
        <mesh filename="meshes/arm/link7_aabb.stl"/>
      </geometry>
    </collision>
  </link>
  <joint name="right_arm_joint7" type="revolute">
    <origin rpy="1.5707963267948966 0 0" xyz="0 0 0"/>
    <parent link="right_arm_link6"/>
    <child link="right_arm_link7"/>
    <axis xyz="0 0 1"/>
    <limit effort="10" lower="-1.57" upper="0.69" velocity="1.5"/>
  </joint>
  <link name="right_arm_end_effector_mount_link"/>
  <joint name="right_arm_end_effector_mount_joint" type="fixed">
    <origin rpy="0 0 0" xyz="0.07 0 0"/>
    <parent link="right_arm_link7"/>
    <child link="right_arm_end_effector_mount_link"/>
    <axis xyz="0 0 0"/>
  </joint>
  <!-- Right Arm Flange: -->
  <!-- Gripper Flange: -->
  
  <joint name="gripper_right_joint" type="fixed">
    <origin rpy="0 1.5707963267948966 0" xyz="0 0 0"/>
    <parent link="right_arm_end_effector_mount_link"/>
    <child link="gripper_right_base_link"/>
  </joint>
  <link name="gripper_right_base_link">
    <inertial>
      <origin rpy="0 0 0" xyz="1.5645E-05 -4.1843E-06 0.038"/>
      <mass value="0.072633"/>
      <inertia ixx="5.095E-05" ixy="-4.256E-14" ixz="2.0229E-08" iyy="6.0883E-05" iyz="-4.5583E-09" izz="1.933E-05"/>
    </inertial>
    <visual>
      <origin rpy="0 0 0" xyz="0 0 0"/>
      <geometry>
        <mesh filename="meshes/gripper/gripper_inspire_base_link.dae"/>
      </geometry>
      <material name="">
        <color rgba="1 1 1 1"/>
      </material>
    </visual>
    <collision>
      <origin rpy="0 0 0" xyz="0 0 0"/>
      <geometry>
        <mesh filename="meshes/gripper/gripper_inspire_base_link_convex.stl"/>
      </geometry>
    </collision>
  </link>
  <link name="gripper_right_left_link">
    <inertial>
      <origin rpy="0 0 0" xyz="-0.018807 -0.0090021 -0.0046901"/>
      <mass value="0.010721"/>
      <inertia ixx="5.1508E-07" ixy="1.2231E-10" ixz="2.8973E-07" iyy="1.5709E-06" iyz="7.2401E-11" izz="1.6904E-06"/>
    </inertial>
    <visual>
      <origin rpy="0 0 0" xyz="0 0 0"/>
      <geometry>
        <mesh filename="meshes/gripper/gripper_inspire_left_link.dae"/>
      </geometry>
      <material name="">
        <color rgba="0.79216 0.81961 0.93333 1"/>
      </material>
    </visual>
    <collision>
      <origin rpy="0 0 0" xyz="0 0 0"/>
      <geometry>
        <mesh filename="meshes/gripper/gripper_inspire_left_link_convex.stl"/>
      </geometry>
    </collision>
  </link>
  <joint name="gripper_right_left_joint" type="prismatic">
    <origin rpy="3.141592653589793 -1.5707963267948966 0" xyz="-0.034907 -0.009 0.12953"/>
    <parent link="gripper_right_base_link"/>
    <child link="gripper_right_left_link"/>
    <axis xyz="0 0 -1"/>
    <limit effort="0" lower="-0.035" upper="0" velocity="2"/>
  </joint>
  <link name="gripper_right_right_link">
    <inertial>
      <origin rpy="0 0 0" xyz="-0.018807 0.0089979 -0.0046901"/>
      <mass value="0.010721"/>
      <inertia ixx="5.1508E-07" ixy="1.2231E-10" ixz="2.8973E-07" iyy="1.5709E-06" iyz="7.2401E-11" izz="1.6904E-06"/>
    </inertial>
    <visual>
      <origin rpy="0 0 0" xyz="0 0 0"/>
      <geometry>
        <mesh filename="meshes/gripper/gripper_inspire_right_link.dae"/>
      </geometry>
      <material name="">
        <color rgba="0.79216 0.81961 0.93333 1"/>
      </material>
    </visual>
    <collision>
      <origin rpy="0 0 0" xyz="0 0 0"/>
      <geometry>
        <mesh filename="meshes/gripper/gripper_inspire_right_link_convex.stl"/>
      </geometry>
    </collision>
  </link>
  <joint name="gripper_right_right_joint" type="prismatic">
    <origin rpy="3.141592653589793 -1.5707963267948966 3.141592653589793" xyz="0.034907 -0.009 0.12953"/>
    <parent link="gripper_right_base_link"/>
    <child link="gripper_right_right_link"/>
    <axis xyz="0 0 1"/>
    <limit effort="0" lower="0" upper="0.035" velocity="2"/>
    <!-- mimic not supported in isaac sim 2023.1.0-hotfix  -->
    <!-- <mimic joint="${name}_right_joint" multiplier="-1" offset="0" /> -->
  </joint>
  <!-- Tool Center Point -->
  <link name="right_gripper_inspire_tcp_frame"/>
  <joint name="gripper_right_tcp_joint" type="fixed">
    <origin rpy="0 3.141592653589793 0" xyz="0 0 0.13751"/>
    <parent link="gripper_right_base_link"/>
    <child link="right_gripper_inspire_tcp_frame"/>
    <axis xyz="0 0 0"/>
  </joint>
</robot>
